Workbook

Sheet Roadmap
A1: SponsorX — Full Programme Roadmap
A2: Six phases (the blueprint's four; the INFINEX game split out on 2026-10-16 and became Phase 6 on 2026-10-27, when the Certified Recruiting partnership took Phase 5), 356 tasks. Each phase has its own sheet. Every task says where the work physically happens.
A4: Phase | B4: Outcome | C4: Tasks | D4: Person-days | E4: Blueprint timeline | F4: Balanced budget | G4: Depends on
A5: Phase 1 | B5: Managed micro-NIL marketplace — the §39 loop working for 25 athletes and 10 businesses | C5: 249 | D5: 601 | E5: 14–18 weeks | F5: $75K–$105K | G5: Nothing — this is the start
A6: Phase 2 | B6: Transactional marketplace: external properties, payments, commission ledger, payouts, wallet rewards | C6: 64 | D6: 260 | E6: 16–20 weeks | F6: $80K–$120K | G6: Phase 1 auth/RBAC, sponsor/property/inventory/campaign/reward models, Zoho integration, core analytics
A7: Phase 3 | B7: Dynamic pricing, sponsor matching, forecasting, attribution and the data platform | C7: 44 | D7: 184 | E7: 18–22 weeks | F7: $105K–$160K | G7: Phase 2 transaction history, campaign performance data, marketplace activity, reliable event ingestion
A8: Phase 4 | B8: INFINEX virtual sponsorship, SponsorX's side as built (all Done). Every open task moved on 2026-10-20 to the game phase (Phase 6 since 2026-10-27): the game is parked | C8: 19 | D8: 62 | E8: 18–22 weeks | F8: $90K–$150K | G8: Stable SponsorX APIs, campaign/reward engine, identity/session model, metrics pipeline
A9: Phase 5 | B9: Certified Recruiting partnership: SponsorX and certified-recruiting.com link to each other (the site is already built on GoDaddy; BTG already links to it) | C9: 2 | D9: 2 | E9: — | F9: — | G9: certified-recruiting.com, live
A10: Phase 6 | B10: INFINEX game integration: the in-game connector, the staging world test, the pilot world, calibrated virtual pricing, and player accounts (email, Google, Apple, authenticator) with a live connection | C10: 50 | D10: 198 | E10: after the game's staging world exists | F10: — | G10: The INFINEX game (not started 2026-10-16), Phase 4's endpoints
A11: TOTAL | B11: Full SponsorX platform | C11: =SUM(C5:C10) | D11: =SUM(D5:D10) | E11: 66–82 weeks | F11: $350K–$535K
A13: WHERE THE WORK HAPPENS
A14: Why this column exists | B14: A task that says 'create the Zoho module' and a task that says 'author the Zoho mapping document' look identical in a list — but one is click-work in an admin UI and the other is a written spec. Every task now states which.
A15: Document | B15: A written decision or specification. No system is touched — the output is a document people agree on.
A16: Zoho dashboard | B16: Configuration clicked through the Zoho CRM admin UI (Setup → Modules and Fields, API credentials, users).
A17: Vendor console | B17: Configuration in a vendor's own UI — Railway, Cloudflare, Clerk, the payment or email provider.
A18: Code | B18: Work in the repository: schema, domain logic, routes, worker jobs, UI, tests, CI.
A19: Code + console | B19: Both: something configured at the vendor AND wired in the codebase.
A20: Design tool | B20: Visual design work producing artwork, diagrams or screen designs.
A21: Document + code | B21: A written policy that must then be enforced in the codebase.
A22: External · counsel | B22: Performed by a lawyer, not the team. Longest lead times in the programme — start these early.
A24: HOW TO READ THIS WORKBOOK
A25: One sheet per phase | B25: Phase 1–5, identical 18 columns, so they behave the same way.
A26: Task IDs | B26: Phase 1: P{stage}-{CAT}-{nn}, e.g. P4-BE-03. Phases 2–6: {phase}S{sprint}-{CAT}-{nn}, e.g. 2S5-BE-04 = Phase 2, Sprint 5, Backend, task 04. IDs never change — cite them in branches and commits.
A27: Order | B27: A dependency-respecting sort key, recomputed whenever tasks are added. It can shift; the ID cannot.
A28: Status | B28: Phase 1 is live. Every Phase 2–4 task starts Blocked because Phase 1 must finish first. Phase 5 (Certified Recruiting) is live. Phase 6 waits for the INFINEX game.
A29: Weight | B29: S=1 · M=3 · L=5 person-days. Estimates for one person, not calendar commitments.
A31: PHASE OVERLAP
A32: Permitted | B32: Begin Phase 3 warehouse and event modelling during the final 4–6 weeks of Phase 2. Begin the Phase 4 API contract and placement taxonomy during the final 4 weeks of Phase 3.
A33: Forbidden | B33: No ML pricing before clean history exists — launch Phase 3 on rules. No marketplace payouts before commission snapshots, reconciliation, refunds/disputes and audit logs are tested. No virtual impressions reported to sponsors before viewability and de-duplication are validated against pilot telemetry (Phase 6, 6S2-QA-01).
A35: SCOPE REALITY
A36: Team size | B36: The blueprint staffs Phase 1 at 4.5–7.5 FTE and Phases 2–4 higher. The team is two people. Phase 1 alone is ~44 weeks at that size. Scope, not stack, is the binding constraint.

Sheet Dashboard
A1: Dashboard
A2: Live formulas across all six phase sheets. Update Status on a phase sheet and this follows. Counts cover the 556 delivery tasks only — the 9 legal/counsel tasks moved to the Legal sheet on 2026-09-15 and are tracked there (565 total). 'External · counsel' therefore reads 0 here.
B4: Ready | C4: In progress | D4: Code review | E4: Blocked | F4: Done | G4: Total | H4: Days left
A5: Phase 1 | B5: =COUNTIF('Phase 1'!$I$5:$I$400,"Ready") | C5: =COUNTIF('Phase 1'!$I$5:$I$400,"In progress") | D5: =COUNTIF('Phase 1'!$I$5:$I$400,"Code review") | E5: =COUNTIF('Phase 1'!$I$5:$I$400,"Blocked") | F5: =COUNTIF('Phase 1'!$I$5:$I$400,"Done") | G5: =COUNTA('Phase 1'!$B$5:$B$400) | H5: =SUMIF('Phase 1'!$I$5:$I$400,"<>Done",'Phase 1'!$J$5:$J$400)
A6: Phase 2 | B6: =COUNTIF('Phase 2'!$I$5:$I$144,"Ready") | C6: =COUNTIF('Phase 2'!$I$5:$I$144,"In progress") | D6: =COUNTIF('Phase 2'!$I$5:$I$144,"Code review") | E6: =COUNTIF('Phase 2'!$I$5:$I$144,"Blocked") | F6: =COUNTIF('Phase 2'!$I$5:$I$144,"Done") | G6: =COUNTA('Phase 2'!$B$5:$B$144) | H6: =SUMIF('Phase 2'!$I$5:$I$144,"<>Done",'Phase 2'!$J$5:$J$144)
A7: Phase 3 | B7: =COUNTIF('Phase 3'!$I$5:$I$66,"Ready") | C7: =COUNTIF('Phase 3'!$I$5:$I$66,"In progress") | D7: =COUNTIF('Phase 3'!$I$5:$I$66,"Code review") | E7: =COUNTIF('Phase 3'!$I$5:$I$66,"Blocked") | F7: =COUNTIF('Phase 3'!$I$5:$I$66,"Done") | G7: =COUNTA('Phase 3'!$B$5:$B$66) | H7: =SUMIF('Phase 3'!$I$5:$I$66,"<>Done",'Phase 3'!$J$5:$J$66)
A8: Phase 4 | B8: =COUNTIF('Phase 4'!$I$5:$I$51,"Ready") | C8: =COUNTIF('Phase 4'!$I$5:$I$51,"In progress") | D8: =COUNTIF('Phase 4'!$I$5:$I$51,"Code review") | E8: =COUNTIF('Phase 4'!$I$5:$I$51,"Blocked") | F8: =COUNTIF('Phase 4'!$I$5:$I$51,"Done") | G8: =COUNTA('Phase 4'!$B$5:$B$51) | H8: =SUMIF('Phase 4'!$I$5:$I$51,"<>Done",'Phase 4'!$J$5:$J$51)
A9: Phase 5 | B9: =COUNTIF('Phase 5'!$I$5:$I$100,"Ready") | C9: =COUNTIF('Phase 5'!$I$5:$I$100,"In progress") | D9: =COUNTIF('Phase 5'!$I$5:$I$100,"Code review") | E9: =COUNTIF('Phase 5'!$I$5:$I$100,"Blocked") | F9: =COUNTIF('Phase 5'!$I$5:$I$100,"Done") | G9: =COUNTA('Phase 5'!$B$5:$B$100) | H9: =SUMIF('Phase 5'!$I$5:$I$100,"<>Done",'Phase 5'!$J$5:$J$100)
A10: Phase 6 | B10: =COUNTIF('Phase 6'!$I$5:$I$100,"Ready") | C10: =COUNTIF('Phase 6'!$I$5:$I$100,"In progress") | D10: =COUNTIF('Phase 6'!$I$5:$I$100,"Code review") | E10: =COUNTIF('Phase 6'!$I$5:$I$100,"Blocked") | F10: =COUNTIF('Phase 6'!$I$5:$I$100,"Done") | G10: =COUNTA('Phase 6'!$B$5:$B$100) | H10: =SUMIF('Phase 6'!$I$5:$I$100,"<>Done",'Phase 6'!$J$5:$J$100)
A11: TOTAL | B11: =SUM(B5:B10) | C11: =SUM(C5:C10) | D11: =SUM(D5:D10) | E11: =SUM(E5:E10) | F11: =SUM(F5:F10) | G11: =SUM(G5:G10) | H11: =SUM(H5:H10)
A12: BY WHERE THE WORK HAPPENS
B13: Phase 1 | C13: Phase 2 | D13: Phase 3 | E13: Phase 4 | F13: Phase 5 | G13: Phase 6 | H13: Total
A14: Document | B14: =COUNTIF('Phase 1'!$F$5:$F$400,"Document") | C14: =COUNTIF('Phase 2'!$F$5:$F$144,"Document") | D14: =COUNTIF('Phase 3'!$F$5:$F$66,"Document") | E14: =COUNTIF('Phase 4'!$F$5:$F$51,"Document") | F14: =COUNTIF('Phase 5'!$F$5:$F$100,"Document") | G14: =COUNTIF('Phase 6'!$F$5:$F$100,"Document") | H14: =SUM(B14:G14)
A15: Zoho dashboard | B15: =COUNTIF('Phase 1'!$F$5:$F$400,"Zoho dashboard") | C15: =COUNTIF('Phase 2'!$F$5:$F$144,"Zoho dashboard") | D15: =COUNTIF('Phase 3'!$F$5:$F$66,"Zoho dashboard") | E15: =COUNTIF('Phase 4'!$F$5:$F$51,"Zoho dashboard") | F15: =COUNTIF('Phase 5'!$F$5:$F$100,"Zoho dashboard") | G15: =COUNTIF('Phase 6'!$F$5:$F$100,"Zoho dashboard") | H15: =SUM(B15:G15)
A16: Vendor console | B16: =COUNTIF('Phase 1'!$F$5:$F$400,"Vendor console") | C16: =COUNTIF('Phase 2'!$F$5:$F$144,"Vendor console") | D16: =COUNTIF('Phase 3'!$F$5:$F$66,"Vendor console") | E16: =COUNTIF('Phase 4'!$F$5:$F$51,"Vendor console") | F16: =COUNTIF('Phase 5'!$F$5:$F$100,"Vendor console") | G16: =COUNTIF('Phase 6'!$F$5:$F$100,"Vendor console") | H16: =SUM(B16:G16)
A17: Code | B17: =COUNTIF('Phase 1'!$F$5:$F$400,"Code") | C17: =COUNTIF('Phase 2'!$F$5:$F$144,"Code") | D17: =COUNTIF('Phase 3'!$F$5:$F$66,"Code") | E17: =COUNTIF('Phase 4'!$F$5:$F$51,"Code") | F17: =COUNTIF('Phase 5'!$F$5:$F$100,"Code") | G17: =COUNTIF('Phase 6'!$F$5:$F$100,"Code") | H17: =SUM(B17:G17)
A18: Code + console | B18: =COUNTIF('Phase 1'!$F$5:$F$400,"Code + console") | C18: =COUNTIF('Phase 2'!$F$5:$F$144,"Code + console") | D18: =COUNTIF('Phase 3'!$F$5:$F$66,"Code + console") | E18: =COUNTIF('Phase 4'!$F$5:$F$51,"Code + console") | F18: =COUNTIF('Phase 5'!$F$5:$F$100,"Code + console") | G18: =COUNTIF('Phase 6'!$F$5:$F$100,"Code + console") | H18: =SUM(B18:G18)
A19: Design tool | B19: =COUNTIF('Phase 1'!$F$5:$F$400,"Design tool") | C19: =COUNTIF('Phase 2'!$F$5:$F$144,"Design tool") | D19: =COUNTIF('Phase 3'!$F$5:$F$66,"Design tool") | E19: =COUNTIF('Phase 4'!$F$5:$F$51,"Design tool") | F19: =COUNTIF('Phase 5'!$F$5:$F$100,"Design tool") | G19: =COUNTIF('Phase 6'!$F$5:$F$100,"Design tool") | H19: =SUM(B19:G19)
A20: Document + code | B20: =COUNTIF('Phase 1'!$F$5:$F$400,"Document + code") | C20: =COUNTIF('Phase 2'!$F$5:$F$144,"Document + code") | D20: =COUNTIF('Phase 3'!$F$5:$F$66,"Document + code") | E20: =COUNTIF('Phase 4'!$F$5:$F$51,"Document + code") | F20: =COUNTIF('Phase 5'!$F$5:$F$100,"Document + code") | G20: =COUNTIF('Phase 6'!$F$5:$F$100,"Document + code") | H20: =SUM(B20:G20)
A21: External · counsel | B21: =COUNTIF('Phase 1'!$F$5:$F$400,"External · counsel") | C21: =COUNTIF('Phase 2'!$F$5:$F$144,"External · counsel") | D21: =COUNTIF('Phase 3'!$F$5:$F$66,"External · counsel") | E21: =COUNTIF('Phase 4'!$F$5:$F$51,"External · counsel") | F21: =COUNTIF('Phase 5'!$F$5:$F$100,"External · counsel") | G21: =COUNTIF('Phase 6'!$F$5:$F$100,"External · counsel") | H21: =SUM(B21:G21)
A23: POLISH · URGENT, BEFORE LAUNCH
B24: Ready | C24: In progress | D24: Code review | E24: Blocked | F24: Done | G24: Total | H24: Days left
A25: Polish | B25: =COUNTIF('Polish'!$I$5:$I$200,"Ready") | C25: =COUNTIF('Polish'!$I$5:$I$200,"In progress") | D25: =COUNTIF('Polish'!$I$5:$I$200,"Code review") | E25: =COUNTIF('Polish'!$I$5:$I$200,"Blocked") | F25: =COUNTIF('Polish'!$I$5:$I$200,"Done") | G25: =COUNTA('Polish'!$B$5:$B$200) | H25: =SUMIF('Polish'!$I$5:$I$200,"<>Done",'Polish'!$J$5:$J$200)
A26: Kept apart from the phase totals above: these fixes cut across phases. Plan in documentation/polish.md.

Sheet Stage Progress
A1: Stage Progress — Phase 1
A2: Live formulas over the Phase 1 sheet — the top block needs no maintenance and is always current. The snapshot below is appended by hand once a day; that is the only part that shows velocity, because a formula cannot remember yesterday. Stage 9 is gated behind B8 and a sold edition — it is in the totals, not in the critical path.
A4: Stage | B4: Stage name | C4: Done | D4: Total | E4: % | F4: Days left | G4: In flight | H4: Blocked
A5: 0 | B5: Foundation & Decisions | C5: =COUNTIFS('Phase 1'!$C$5:$C$400,$A5,'Phase 1'!$I$5:$I$400,"Done") | D5: =COUNTIF('Phase 1'!$C$5:$C$400,$A5) | E5: =IF($D5=0,0,$C5/$D5) | F5: =SUMIFS('Phase 1'!$J$5:$J$400,'Phase 1'!$C$5:$C$400,$A5,'Phase 1'!$I$5:$I$400,"<>Done") | G5: =COUNTIFS('Phase 1'!$C$5:$C$400,$A5,'Phase 1'!$I$5:$I$400,"In progress")+COUNTIFS('Phase 1'!$C$5:$C$400,$A5,'Phase 1'!$I$5:$I$400,"Code review") | H5: =COUNTIFS('Phase 1'!$C$5:$C$400,$A5,'Phase 1'!$I$5:$I$400,"Blocked")
A6: 1 | B6: UI Scaffold on Fixtures | C6: =COUNTIFS('Phase 1'!$C$5:$C$400,$A6,'Phase 1'!$I$5:$I$400,"Done") | D6: =COUNTIF('Phase 1'!$C$5:$C$400,$A6) | E6: =IF($D6=0,0,$C6/$D6) | F6: =SUMIFS('Phase 1'!$J$5:$J$400,'Phase 1'!$C$5:$C$400,$A6,'Phase 1'!$I$5:$I$400,"<>Done") | G6: =COUNTIFS('Phase 1'!$C$5:$C$400,$A6,'Phase 1'!$I$5:$I$400,"In progress")+COUNTIFS('Phase 1'!$C$5:$C$400,$A6,'Phase 1'!$I$5:$I$400,"Code review") | H6: =COUNTIFS('Phase 1'!$C$5:$C$400,$A6,'Phase 1'!$I$5:$I$400,"Blocked")
A7: 2 | B7: Platform Foundations | C7: =COUNTIFS('Phase 1'!$C$5:$C$400,$A7,'Phase 1'!$I$5:$I$400,"Done") | D7: =COUNTIF('Phase 1'!$C$5:$C$400,$A7) | E7: =IF($D7=0,0,$C7/$D7) | F7: =SUMIFS('Phase 1'!$J$5:$J$400,'Phase 1'!$C$5:$C$400,$A7,'Phase 1'!$I$5:$I$400,"<>Done") | G7: =COUNTIFS('Phase 1'!$C$5:$C$400,$A7,'Phase 1'!$I$5:$I$400,"In progress")+COUNTIFS('Phase 1'!$C$5:$C$400,$A7,'Phase 1'!$I$5:$I$400,"Code review") | H7: =COUNTIFS('Phase 1'!$C$5:$C$400,$A7,'Phase 1'!$I$5:$I$400,"Blocked")
A8: 3 | B8: Athlete Network | C8: =COUNTIFS('Phase 1'!$C$5:$C$400,$A8,'Phase 1'!$I$5:$I$400,"Done") | D8: =COUNTIF('Phase 1'!$C$5:$C$400,$A8) | E8: =IF($D8=0,0,$C8/$D8) | F8: =SUMIFS('Phase 1'!$J$5:$J$400,'Phase 1'!$C$5:$C$400,$A8,'Phase 1'!$I$5:$I$400,"<>Done") | G8: =COUNTIFS('Phase 1'!$C$5:$C$400,$A8,'Phase 1'!$I$5:$I$400,"In progress")+COUNTIFS('Phase 1'!$C$5:$C$400,$A8,'Phase 1'!$I$5:$I$400,"Code review") | H8: =COUNTIFS('Phase 1'!$C$5:$C$400,$A8,'Phase 1'!$I$5:$I$400,"Blocked")
A9: 4 | B9: Sponsor Demand & Matching | C9: =COUNTIFS('Phase 1'!$C$5:$C$400,$A9,'Phase 1'!$I$5:$I$400,"Done") | D9: =COUNTIF('Phase 1'!$C$5:$C$400,$A9) | E9: =IF($D9=0,0,$C9/$D9) | F9: =SUMIFS('Phase 1'!$J$5:$J$400,'Phase 1'!$C$5:$C$400,$A9,'Phase 1'!$I$5:$I$400,"<>Done") | G9: =COUNTIFS('Phase 1'!$C$5:$C$400,$A9,'Phase 1'!$I$5:$I$400,"In progress")+COUNTIFS('Phase 1'!$C$5:$C$400,$A9,'Phase 1'!$I$5:$I$400,"Code review") | H9: =COUNTIFS('Phase 1'!$C$5:$C$400,$A9,'Phase 1'!$I$5:$I$400,"Blocked")
A10: 5 | B10: Campaign Execution | C10: =COUNTIFS('Phase 1'!$C$5:$C$400,$A10,'Phase 1'!$I$5:$I$400,"Done") | D10: =COUNTIF('Phase 1'!$C$5:$C$400,$A10) | E10: =IF($D10=0,0,$C10/$D10) | F10: =SUMIFS('Phase 1'!$J$5:$J$400,'Phase 1'!$C$5:$C$400,$A10,'Phase 1'!$I$5:$I$400,"<>Done") | G10: =COUNTIFS('Phase 1'!$C$5:$C$400,$A10,'Phase 1'!$I$5:$I$400,"In progress")+COUNTIFS('Phase 1'!$C$5:$C$400,$A10,'Phase 1'!$I$5:$I$400,"Code review") | H10: =COUNTIFS('Phase 1'!$C$5:$C$400,$A10,'Phase 1'!$I$5:$I$400,"Blocked")
A11: 6 | B11: Measurement & Reward | C11: =COUNTIFS('Phase 1'!$C$5:$C$400,$A11,'Phase 1'!$I$5:$I$400,"Done") | D11: =COUNTIF('Phase 1'!$C$5:$C$400,$A11) | E11: =IF($D11=0,0,$C11/$D11) | F11: =SUMIFS('Phase 1'!$J$5:$J$400,'Phase 1'!$C$5:$C$400,$A11,'Phase 1'!$I$5:$I$400,"<>Done") | G11: =COUNTIFS('Phase 1'!$C$5:$C$400,$A11,'Phase 1'!$I$5:$I$400,"In progress")+COUNTIFS('Phase 1'!$C$5:$C$400,$A11,'Phase 1'!$I$5:$I$400,"Code review") | H11: =COUNTIFS('Phase 1'!$C$5:$C$400,$A11,'Phase 1'!$I$5:$I$400,"Blocked")
A12: 7 | B12: Money & Reporting | C12: =COUNTIFS('Phase 1'!$C$5:$C$400,$A12,'Phase 1'!$I$5:$I$400,"Done") | D12: =COUNTIF('Phase 1'!$C$5:$C$400,$A12) | E12: =IF($D12=0,0,$C12/$D12) | F12: =SUMIFS('Phase 1'!$J$5:$J$400,'Phase 1'!$C$5:$C$400,$A12,'Phase 1'!$I$5:$I$400,"<>Done") | G12: =COUNTIFS('Phase 1'!$C$5:$C$400,$A12,'Phase 1'!$I$5:$I$400,"In progress")+COUNTIFS('Phase 1'!$C$5:$C$400,$A12,'Phase 1'!$I$5:$I$400,"Code review") | H12: =COUNTIFS('Phase 1'!$C$5:$C$400,$A12,'Phase 1'!$I$5:$I$400,"Blocked")
A13: 8 | B13: Integration, Hardening & Launch | C13: =COUNTIFS('Phase 1'!$C$5:$C$400,$A13,'Phase 1'!$I$5:$I$400,"Done") | D13: =COUNTIF('Phase 1'!$C$5:$C$400,$A13) | E13: =IF($D13=0,0,$C13/$D13) | F13: =SUMIFS('Phase 1'!$J$5:$J$400,'Phase 1'!$C$5:$C$400,$A13,'Phase 1'!$I$5:$I$400,"<>Done") | G13: =COUNTIFS('Phase 1'!$C$5:$C$400,$A13,'Phase 1'!$I$5:$I$400,"In progress")+COUNTIFS('Phase 1'!$C$5:$C$400,$A13,'Phase 1'!$I$5:$I$400,"Code review") | H13: =COUNTIFS('Phase 1'!$C$5:$C$400,$A13,'Phase 1'!$I$5:$I$400,"Blocked")
A14: 9 | B14: SponsorX NEXT (gated) | C14: =COUNTIFS('Phase 1'!$C$5:$C$400,$A14,'Phase 1'!$I$5:$I$400,"Done") | D14: =COUNTIF('Phase 1'!$C$5:$C$400,$A14) | E14: =IF($D14=0,0,$C14/$D14) | F14: =SUMIFS('Phase 1'!$J$5:$J$400,'Phase 1'!$C$5:$C$400,$A14,'Phase 1'!$I$5:$I$400,"<>Done") | G14: =COUNTIFS('Phase 1'!$C$5:$C$400,$A14,'Phase 1'!$I$5:$I$400,"In progress")+COUNTIFS('Phase 1'!$C$5:$C$400,$A14,'Phase 1'!$I$5:$I$400,"Code review") | H14: =COUNTIFS('Phase 1'!$C$5:$C$400,$A14,'Phase 1'!$I$5:$I$400,"Blocked")
B15: TOTAL | C15: =SUM(C5:C14) | D15: =SUM(D5:D14) | E15: =IF($D15=0,0,$C15/$D15) | F15: =SUM(F5:F14) | G15: =SUM(G5:G14) | H15: =SUM(H5:H14)
A17: DAILY SNAPSHOT
A18: One row per day, appended at end of day. Literal numbers, never formulas — a snapshot that recalculates is not a snapshot.
A19: Date | B19: S0 | C19: S1 | D19: S2 | E19: S3 | F19: S4 | G19: S5 | H19: S6 | I19: S7 | J19: S8 | K19: S9 | L19: Done | M19: Days left
A20: 2026-09-22 | B20: 22 | C20: 21 | D20: 18 | E20: 16 | F20: 8 | G20: 3 | H20: 0 | I20: 0 | J20: 0 | K20: 0 | L20: 88 | M20: 433
A21: 2026-09-23 | B21: 25 | C21: 21 | D21: 18 | E21: 17 | F21: 9 | G21: 11 | H21: 8 | I21: 12 | J21: 0 | K21: 0 | L21: 91 | M21: 428
A22: 2026-09-24 | B22: 25 | C22: 21 | D22: 19 | E22: 18 | F22: 10 | G22: 11 | H22: 11 | I22: 12 | J22: 12 | K22: 0 | L22: 139 | M22: 308
A23: 2026-09-25 | B23: 25 | C23: 21 | D23: 19 | E23: 18 | F23: 10 | G23: 11 | H23: 11 | I23: 12 | J23: 13 | K23: 0 | L23: 140 | M23: 305
A24: 2026-09-28 | B24: 25 | C24: 38 | D24: 19 | E24: 24 | F24: 16 | G24: 17 | H24: 17 | I24: 19 | J24: 18 | K24: 26 | L24: 219 | M24: 77
A25: 2026-09-29 | B25: 25 | C25: 38 | D25: 21 | E25: 26 | F25: 16 | G25: 17 | H25: 17 | I25: 19 | J25: 18 | K25: 26 | L25: 223 | M25: 79
A26: 2026-09-30 | B26: 25 | C26: 38 | D26: 21 | E26: 26 | F26: 16 | G26: 17 | H26: 17 | I26: 19 | J26: 18 | K26: 26 | L26: 223 | M26: 93
A27: 2026-10-01 | B27: 25 | C27: 42 | D27: 21 | E27: 29 | F27: 18 | G27: 17 | H27: 19 | I27: 20 | J27: 18 | K27: 27 | L27: 236 | M27: 60
A28: 2026-10-02 | B28: 25 | C28: 46 | D28: 23 | E28: 29 | F28: 18 | G28: 17 | H28: 19 | I28: 20 | J28: 18 | K28: 28 | L28: 243 | M28: 50
A29: 2026-10-05 | B29: 25 | C29: 47 | D29: 23 | E29: 29 | F29: 27 | G29: 19 | H29: 20 | I29: 20 | J29: 18 | K29: 37 | L29: 265 | M29: 47
A30: 2026-10-07 | B30: 25 | C30: 47 | D30: 23 | E30: 29 | F30: 27 | G30: 19 | H30: 20 | I30: 20 | J30: 18 | K30: 37 | L30: 265 | M30: 58.5
A31: 2026-10-08 | B31: 26 | C31: 56 | D31: 25 | E31: 29 | F31: 27 | G31: 19 | H31: 20 | I31: 20 | J31: 19 | K31: 37 | L31: 278 | M31: 37
... A42: 2026-10-28 | B42: 28 | C42: 62 | D42: 25 | E42: 29 | F42: 27 | G42: 19 | H42: 20 | I42: 20 | J42: 45 | K42: 38 | L42: 313 | M42: 23.5

Sheet Polish
A1: SponsorX — Polish · Fix before launch (URGENT)
A2: 53 tasks across 36 user-experience flaws found 2026-10-28 · do these before cleaning up any other task on the board · do POL-BE-04 first (hurting sponsors now, while Stripe is paused) · plan: documentation/polish.md
A4: Order | B4: ID | C4: Stage | D4: Stage name | E4: Cat | F4: Where the work happens | G4: Task | H4: DETAILS | I4: Status | J4: Weight (days) | K4: Date Started | L4: Date Done | M4: Owner | N4: Unblocks | O4: Depends On | P4: Acceptance Criteria | Q4: Refs | R4: Notes
A5: 1 | B5: POL-BE-01 | C5: 1 | D5: A · Money, minors, consent | E5: BE | F5: Code | G5: Payouts stop going to the old guardian | H5: After a guardian handoff or coming of age, the old payout account stops receiving money (PayoutAccount is unique per athlete, so it is reused today). Payouts wait for the new holder's own account; both are told. | I5: Done | J5: 2 | K5: 46323 | L5: 46323 | M5: rcfworks | N5: 1 | P5: No payout reaches the old account after a handoff or coming of age; new holder asked to set up; tests | Q5: polish.md #1 | R5: Raised 2026-10-28 from the UX review. Rule decided 2026-10-28: anything not yet paid out follows the athlete to the new holder.
A6: 2 | B6: POL-FE-01 | C6: 1 | D6: A · Money, minors, consent | E6: FE | F6: Code | G6: New guardian or adult athlete sets up payouts | H6: After a handoff or coming of age, the payouts screen asks the new holder to set up their own account and shows payouts waiting. | I6: Ready | J6: 1 | M6: HeckerCreatives | N6: 0 | O6: POL-BE-01 | P6: New holder sees the prompt and waiting payouts; old holder no longer sees the account | Q6: polish.md #1 | R6: Raised 2026-10-28 from the UX review.
A7: 3 | B7: POL-BE-02 | C7: 1 | D7: A · Money, minors, consent | E7: BE | F7: Code | G7: A minor's date-of-birth change and coming-of-age takeover are held | H7: While a minor, a DOB change is held for the guardian and BTG instead of applying at once. A coming-of-age takeover is always held for BTG, even when the ID reads clear. | I7: Done | J7: 2 | K7: 46323 | L7: 46323 | M7: rcfworks | N7: 1 | P7: Minor's DOB change waits for approval; coming of age never removes a guardian without BTG; tests | Q7: polish.md #2 | R7: Raised 2026-10-28 from the UX review. Decided 2026-10-28: BTG alone approves a change that would make a minor an adult; takeover automatic only when the ID reads clear.
A8: 4 | B8: POL-FE-02 | C8: 1 | D8: A · Money, minors, consent | E8: FE | F8: Code | G8: DOB change shows 'waiting for approval' | H8: Profile edit shows a minor's DOB change as waiting; guardian and BTG see Approve / Decline. | I8: Ready | J8: 1 | M8: HeckerCreatives | N8: 0 | O8: POL-BE-02 | P8: Minor sees waiting state; guardian and BTG can approve or decline | Q8: polish.md #2 | R8: Raised 2026-10-28 from the UX review.
A9: 5 | B9: POL-BE-03 | C9: 1 | D9: A · Money, minors, consent | E9: BE | F9: Code | G9: A team can't raise its share without the athlete's yes | H9: Any share raise (directly added athletes included, not just invited) needs the athlete's agreement, the guardian's for a minor. Lowering applies at once. Both emailed. | I9: Done | J9: 2 | K9: 46324 | L9: 46324 | M9: rcfworks | N9: 1 | P9: No share goes up without the athlete's or guardian's yes; tests for direct, invited and minor | Q9: polish.md #3 | R9: Raised 2026-10-28 from the UX review. Decided 2026-10-29: the share typed at Add athlete needs the athlete's yes too; BTG's standard share applies until then. PR #322.
A10: 6 | B10: POL-FE-03 | C10: 1 | D10: A · Money, minors, consent | E10: FE | F10: Code | G10: Accept or decline a team share change | H10: Athlete or guardian screen showing old and new share with Accept / Decline; team sees 'waiting for the athlete'. | I10: Ready | J10: 1 | M10: HeckerCreatives | N10: 0 | O10: POL-BE-03 | P10: Athlete or guardian can accept or decline; team sees the pending state | Q10: polish.md #3 | R10: Raised 2026-10-28 from the UX review.
A11: 7 | B11: POL-BE-04 | C11: 1 | D11: A · Money, minors, consent | E11: BE | F11: Code | G11: No reminders or cancellations while payment is off | H11: sweepUnpaidOrders and the reminders skip orders while the payment provider is off; the countdown starts when payment opens. Hurting sponsors now, while Stripe is paused. | I11: Done | J11: 1 | K11: 46323 | L11: 46323 | M11: rcfworks | N11: 1 | P11: With payment off no reminder and no cancellation; with it on unchanged; tests | Q11: polish.md #4 | R11: Raised 2026-10-28 from the UX review.
A12: 8 | B12: POL-FE-04 | C12: 1 | D12: A · Money, minors, consent | E12: FE | F12: Code | G12: Checkout says payment opens later | H12: Checkout and order page say plainly that payment is not open yet and the order is held, not cancelled. | I12: Ready | J12: 0.5 | M12: HeckerCreatives | N12: 0 | O12: POL-BE-04 | P12: Sponsor sees the order is held until payment opens | Q12: polish.md #4 | R12: Raised 2026-10-28 from the UX review.
A13: 9 | B13: POL-BE-05 | C13: 1 | D13: A · Money, minors, consent | E13: BE | F13: Code | G13: Order quote with fees before placing | H13: A quote endpoint returns subtotal, fees and total before the order is placed (skip if one already exists). | I13: Done | J13: 1 | K13: 46324 | L13: 46324 | M13: rcfworks | N13: 1 | P13: Quote total equals the charged total; tests | Q13: polish.md #5 | R13: Raised 2026-10-28 from the UX review. PR #324: the cart, the held checkout and placing carry a quote (subtotal, fees, total); placing refuses a changed total.
A14: 10 | B14: POL-FE-05 | C14: 1 | D14: A · Money, minors, consent | E14: FE | F14: Code | G14: Checkout shows the full total before committing | H14: Replace 'Fees: added when the order is placed' and 'Total so far' with the real total next to the button that commits. | I14: Ready | J14: 0.5 | M14: HeckerCreatives | N14: 0 | O14: POL-BE-05 | P14: Total shown before placing equals the total charged | Q14: polish.md #5 | R14: Raised 2026-10-28 from the UX review.
A15: 11 | B15: POL-BE-06 | C15: 1 | D15: A · Money, minors, consent | E15: BE | F15: Code | G15: Duplicate payment creates a refund to send | H15: A duplicate payment adds a row to Refunds to send and flags the order; BTG can mark it refunded. | I15: Done | J15: 1 | K15: 46324 | L15: 46324 | M15: rcfworks | N15: 1 | P15: Duplicate shows in Refunds to send and on the order; tests | Q15: polish.md #6 | R15: Raised 2026-10-28 from the UX review. PR #325: a card payment confirmed for an order already paid (PAID_TWICE) or refunded (PAID_AFTER_REFUND) is its own refund row; refunds of extra payments never shorten the order's own.
A16: 12 | B16: POL-FE-06 | C16: 1 | D16: A · Money, minors, consent | E16: FE | F16: Code | G16: Order page shows a duplicate payment | H16: Order page shows the duplicate and its refund status; BTG gets a Mark refunded button. | I16: Ready | J16: 0.5 | M16: HeckerCreatives | N16: 0 | O16: POL-BE-06 | P16: Sponsor and BTG see the duplicate and refund status | Q16: polish.md #6 | R16: Raised 2026-10-28 from the UX review.
A17: 13 | B17: POL-BE-07 | C17: 1 | D17: A · Money, minors, consent | E17: BE | F17: Code | G17: Staff redeem needs a venue code, with undo | H17: Redeem requires a staff PIN per reward or event; a redeem can be undone within a few minutes. | I17: Ready | J17: 2 | M17: rcfworks | N17: 1 | P17: No redeem without the venue code; undo works in the window; tests | Q17: polish.md #7 | R17: Raised 2026-10-28 from the UX review.
A18: 14 | B18: POL-FE-07 | C18: 1 | D18: A · Money, minors, consent | E18: FE | F18: Code | G18: Fan page asks for the staff code | H18: 'Staff: redeem now' asks for the code and confirms; shows Undo for a few minutes. | I18: Ready | J18: 1 | M18: HeckerCreatives | N18: 0 | O18: POL-BE-07 | P18: Redeem needs the code and a confirmation; undo shown | Q18: polish.md #7 | R18: Raised 2026-10-28 from the UX review.
A19: 15 | B19: POL-BE-08 | C19: 1 | D19: A · Money, minors, consent | E19: BE | F19: Code | G19: Each fan gets their own claim on a shared code | H19: Claims are per fan, not per code, up to the reward's limit; later fans' emails are collected. | I19: Ready | J19: 2 | M19: rcfworks | N19: 1 | P19: Two fans on one code each get their own claim; tests | Q19: polish.md #8 | R19: Raised 2026-10-28 from the UX review.
A20: 16 | B20: POL-FE-08 | C20: 1 | D20: A · Money, minors, consent | E20: FE | F20: Code | G20: Fan page shows the fan's own claim | H20: The page shows this fan's claim, or 'all claimed', never another fan's hold. | I20: Ready | J20: 0.5 | M20: HeckerCreatives | N20: 0 | O20: POL-BE-08 | P20: Each fan sees only their own claim | Q20: polish.md #8 | R20: Raised 2026-10-28 from the UX review.
A21: 17 | B21: POL-BE-09 | C21: 2 | D21: B · Waiting or stuck | E21: BE | F21: Code | G21: A minor's invitation emails go to the guardian | H21: Invitation, reminder and expiry emails for a minor go to the guardian (copy to the minor); today they go only to the minor (notify-invitation.mts). | I21: Ready | J21: 1 | M21: rcfworks | N21: 0 | P21: Guardian gets every email for a minor's invitation; tests | Q21: polish.md #9 | R21: Raised 2026-10-28 from the UX review.
A22: 18 | B22: POL-BE-10 | C22: 2 | D22: B · Waiting or stuck | E22: BE | F22: Code | G22: Guardian handoff reminders and escalation | H22: Remind the current guardian after 3 days; escalate to BTG after 7, who can decide with the documents. | I22: Ready | J22: 2 | M22: rcfworks | N22: 1 | P22: Reminders and escalation on schedule; BTG decides an escalated handoff; tests | Q22: polish.md #10 | R22: Raised 2026-10-28 from the UX review.
A23: 19 | B23: POL-FE-10 | C23: 2 | D23: B · Waiting or stuck | E23: FE | F23: Code | G23: Handoff desk shows age and BTG decide | H23: Handoff desk shows how long each has waited and a Decide button on escalated ones. | I23: Ready | J23: 0.5 | M23: HeckerCreatives | N23: 0 | O23: POL-BE-10 | P23: BTG sees age and can decide escalated handoffs | Q23: polish.md #10 | R23: Raised 2026-10-28 from the UX review.
A24: 20 | B24: POL-BE-11 | C24: 2 | D24: B · Waiting or stuck | E24: BE | F24: Code | G24: Account closure settles live deals first | H24: With live deals, closing is held for BTG, which settles each deal and tells the sponsor. A minor's closure needs the guardian. Earned money pays to the account on file without a login. | I24: Ready | J24: 2 | M24: rcfworks | N24: 1 | P24: No closure leaves a live deal unsettled or unannounced; a minor can't close alone; earned money still pays; tests | Q24: polish.md #11 | R24: Raised 2026-10-28 from the UX review.
A25: 21 | B25: POL-FE-11 | C25: 2 | D25: B · Waiting or stuck | E25: FE | F25: Code | G25: Closing screen lists live deals | H25: Before confirming, list the live deals and what happens to each; fix the payout promise wording. | I25: Ready | J25: 0.5 | M25: HeckerCreatives | N25: 0 | O25: POL-BE-11 | P25: Closing screen shows live deals and accurate payout wording | Q25: polish.md #11 | R25: Raised 2026-10-28 from the UX review.
A26: 22 | B26: POL-BE-12 | C26: 2 | D26: B · Waiting or stuck | E26: BE | F26: Code | G26: Held payouts email BTG and are counted | H26: A held payout emails BTG Finance with the reason and is included in the dashboard counts. | I26: Ready | J26: 1 | M26: rcfworks | N26: 1 | P26: Every held payout emails and is counted; tests | Q26: polish.md #12 | R26: Raised 2026-10-28 from the UX review.
A27: 23 | B27: POL-FE-12 | C27: 2 | D27: B · Waiting or stuck | E27: FE | F27: Code | G27: Held payouts on the BTG dashboard | H27: Dashboard tile for held payouts, linked to the queue. | I27: Ready | J27: 0.5 | M27: HeckerCreatives | N27: 0 | O27: POL-BE-12 | P27: Tile shows the count and opens the queue | Q27: polish.md #12 | R27: Raised 2026-10-28 from the UX review.
A28: 24 | B28: POL-FE-13 | C28: 2 | D28: B · Waiting or stuck | E28: FE | F28: Code | G28: Sponsor invoices screen | H28: 'Invoices to pay' and Billing open an invoices screen (GET /campaigns/{id}/invoices already exists) listing each invoice, status and a pay link. | I28: Ready | J28: 1.5 | M28: HeckerCreatives | N28: 0 | P28: Sponsor can open, see and pay every invoice | Q28: polish.md #13 | R28: Raised 2026-10-28 from the UX review.
A29: 25 | B29: POL-BE-14 | C29: 2 | D29: B · Waiting or stuck | E29: BE | F29: Code | G29: Held make-goods email BTG and are counted | H29: A held make-good emails BTG and is included in the dashboard counts (POL-BE-15). | I29: Ready | J29: 0.5 | M29: rcfworks | N29: 0 | P29: Every held make-good emails and is counted; tests | Q29: polish.md #14 | R29: Raised 2026-10-28 from the UX review.
A30: 26 | B30: POL-BE-15 | C30: 2 | D30: B · Waiting or stuck | E30: BE | F30: Code | G30: One counts endpoint for every BTG queue | H30: Counts for sign-ups, organisations, sponsor requests, handoffs, held listings and orders, delivery issues, payouts and make-goods, plus the existing four, with the oldest item's age. | I30: Ready | J30: 1.5 | M30: rcfworks | N30: 1 | P30: Every queue that waits on BTG has a count; roles and tenants enforced; tests | Q30: polish.md #15 | R30: Raised 2026-10-28 from the UX review.
A31: 27 | B31: POL-FE-15 | C31: 2 | D31: B · Waiting or stuck | E31: FE | F31: Code | G31: BTG dashboard shows every queue | H31: One tile per queue with its count and oldest age, linked to the queue. | I31: Ready | J31: 1 | M31: HeckerCreatives | N31: 0 | O31: POL-BE-15 | P31: Every BTG queue has a tile linked to it | Q31: polish.md #15 | R31: Raised 2026-10-28 from the UX review.
A32: 28 | B32: POL-FE-16 | C32: 3 | D32: C · Confusing or extra work | E32: FE | F32: Code | G32: Change guardian email at /join | H32: Add 'Change guardian email' on the /join status page (the API already allows it). | I32: Ready | J32: 0.5 | M32: HeckerCreatives | N32: 0 | P32: A mistyped guardian email can be fixed and the invite resent | Q32: polish.md #16 | R32: Raised 2026-10-28 from the UX review.
A33: 29 | B33: POL-BE-17 | C33: 3 | D33: C · Confusing or extra work | E33: BE | F33: Code | G33: Withdraw a sponsor request | H33: Add withdraw for a sent request if missing; confirm PATCH /briefs covers edit while editable. | I33: Ready | J33: 0.5 | M33: rcfworks | N33: 1 | P33: Sponsor can withdraw; edit allowed only while editable; tests | Q33: polish.md #17 | R33: Raised 2026-10-28 from the UX review.
A34: 30 | B34: POL-FE-17 | C34: 3 | D34: C · Confusing or extra work | E34: FE | F34: Code | G34: Sponsor request detail with Edit and Withdraw | H34: The request opens to a detail page with Edit (while editable) and Withdraw. | I34: Ready | J34: 1 | M34: HeckerCreatives | N34: 0 | O34: POL-BE-17 | P34: Sponsor can open, edit and withdraw a request | Q34: polish.md #17 | R34: Raised 2026-10-28 from the UX review.
A35: 31 | B35: POL-BE-18 | C35: 3 | D35: C · Confusing or extra work | E35: BE | F35: Code | G35: Resend and change the request confirmation email | H35: Endpoints to resend the confirmation email and change the address, rate limited (if missing). | I35: Ready | J35: 0.5 | M35: rcfworks | N35: 1 | P35: Resend and change work, rate limited; tests | Q35: polish.md #18 | R35: Raised 2026-10-28 from the UX review.
A36: 32 | B36: POL-FE-18 | C36: 3 | D36: C · Confusing or extra work | E36: FE | F36: Code | G36: Resend email and Change email on the request status | H36: Buttons on the sponsor request status page. | I36: Ready | J36: 0.5 | M36: HeckerCreatives | N36: 0 | O36: POL-BE-18 | P36: Sponsor can resend or fix the address | Q36: polish.md #18 | R36: Raised 2026-10-28 from the UX review.
A37: 33 | B37: POL-BE-19 | C37: 3 | D37: C · Confusing or extra work | E37: BE | F37: Code | G37: Sponsor admin invites teammates | H37: Invite by email and set roles within the sponsor's own organisation (if the API lacks it). | I37: Ready | J37: 1.5 | M37: rcfworks | N37: 1 | P37: Invite and role change work; own tenant only; tests | Q37: polish.md #19 | R37: Raised 2026-10-28 from the UX review.
A38: 34 | B38: POL-FE-19 | C38: 3 | D38: C · Confusing or extra work | E38: FE | F38: Code | G38: Sponsor team screen; hide dead menu items | H38: Team screen to invite and set roles; hide Settings and Messages until they work. | I38: Ready | J38: 1 | M38: HeckerCreatives | N38: 0 | O38: POL-BE-19 | P38: Sponsor admin can invite teammates; no dead menu items | Q38: polish.md #19 | R38: Raised 2026-10-28 from the UX review.
A39: 35 | B39: POL-FE-20 | C39: 3 | D39: C · Confusing or extra work | E39: FE | F39: Code | G39: 'Needs your OK' only when there is an action | H39: Show it only when the sponsor has an action, linked straight to it. | I39: Ready | J39: 0.5 | M39: HeckerCreatives | N39: 0 | P39: Never shown without a sponsor action; links to it | Q39: polish.md #20 | R39: Raised 2026-10-28 from the UX review.
A40: 36 | B40: POL-FE-21 | C40: 3 | D40: C · Confusing or extra work | E40: FE | F40: Code | G40: Request progress steps follow the real state | H40: No 'Price agreed' or 'Campaign live' before they happen. | I40: Ready | J40: 0.5 | M40: HeckerCreatives | N40: 0 | P40: Steps match the request's real state | Q40: polish.md #21 | R40: Raised 2026-10-28 from the UX review.
A41: 37 | B41: POL-BE-22 | C41: 3 | D41: C · Confusing or extra work | E41: BE | F41: Code | G41: Mark a stalled campaign | H41: The API flags a campaign whose staffing has stalled and when BTG stepped in. | I41: Ready | J41: 0.5 | M41: rcfworks | N41: 1 | P41: Stalled campaigns flagged; tests | Q41: polish.md #22 | R41: Raised 2026-10-28 from the UX review.
...

Sheet Phase 1
A1: SponsorX — Phase 1 · Managed Marketplace
A2: 269 tasks · 615 person-days · the loop that must work before anything else is built · Stage 9 (SponsorX NEXT, spec v2.0) is gated, not queued
A4: Order | B4: ID | C4: Stage | D4: Stage name | E4: Cat | F4: Where the work happens | G4: Task | H4: DETAILS | I4: Status | J4: Weight (days) | K4: Date Started | L4: Date Done | M4: Owner | N4: Unblocks | O4: Depends On | P4: Acceptance Criteria | Q4: Refs | R4: Notes
A5: 0 | B5: P0-PMO-02 | C5: 0 | D5: Foundation & Decisions | E5: PMO | F5: Document | G5: Confirm data residency and set regions (G-02) | H5: DECISION GATE G-02 · Data residency — which region do Railway and R2 run in? — Pick the geographic region Railway and Cloudflare R2 run in, and write it down. Almost certainly US-only: NIL is US law, sponsors are local US businesses, minors' data is involved. Moving a database region later is painful, so this is decided before anything exists. | I5: Done | J5: 1 | N5: 2 | P5: Railway region and R2 region chosen explicitly, recorded, not left at defaults | Q5: Addendum A7
A6: 0 | B6: P1-ART-01 | C6: 1 | D6: UI Scaffold on Fixtures | E6: ART | F6: Design tool | G6: Brand retheme — mockup v1.0 purple/teal → BTG logo blue/orange | H6: Already shipped. The whole app was re-themed from the old mockup purple to the BTG logo's blue and orange via one token file. | I6: Done | P6: Token swap in globals.css; ground #0A0C10, primary #2E9BF5, accent #F97A1F, warn #FACC15; portal accents follow the logo | R6: Shipped before this plan
A7: 0 | B7: P1-ART-02 | C7: 1 | D7: UI Scaffold on Fixtures | E7: ART | F7: Design tool | G7: Wire official logo assets | H7: Already shipped. Official logo artwork wired into login, portal headers, marketing hero and the browser tab icon. | I7: Done | P7: sponsorx-badge/title/full.png in public/; Logo component; favicon via src/app/icon.png | R7: Shipped before this plan
A8: 0 | B8: P1-ART-03 | C8: 1 | D8: UI Scaffold on Fixtures | E8: ART | F8: Design tool | G8: Sponsor portal redesign — Command Deck + Executive Bento + radial ROI gauge | H8: Already shipped. The four sponsor-facing pages redesigned for client-demo quality, including the radial ROI gauge. | I8: Done | P8: Spec and plan under docs/superpowers/; shipped across 9 commits | R8: Shipped before this plan
A9: 0 | B9: P1-FE-01 | C9: 1 | D9: UI Scaffold on Fixtures | E9: FE | F9: Code | G9: Build the 10 remaining stub routes on fixtures | H9: Already shipped. The last ten placeholder screens were built out, so every portal is fully navigable on mock data. | I9: Done | P9: join, athlete/invitations, athlete/orders/[id], athlete/earnings, admin, admin/applications, admin/approvals, admin/finance, packages, property — no ScreenStub remains | R9: Shipped before this plan
A10: 0 | B10: P1-FE-02 | C10: 1 | D10: UI Scaffold on Fixtures | E10: FE | F10: Code | G10: State & polish pass across all routes (A2) | H10: Already shipped. Loading, empty and error states across all 25 routes, plus the light theme and responsive behaviour. | I10: Done | N10: 2 | P10: Loading / empty / error states; light theme; responsive; 25 routes build green | R10: Shipped before this plan
A11: 0 | B11: P1-FE-03 | C11: 1 | D11: UI Scaffold on Fixtures | E11: FE | F11: Code | G11: No-JS accessible fan redeem page | H11: Already shipped. The fan redeem page renders with JavaScript disabled and passes accessibility checks. | I11: Done | P11: r/[token] renders without JavaScript, branded, a11y-checked | R11: Shipped before this plan
A12: 1 | B12: P0-OPS-01 | C12: 0 | D12: Foundation & Decisions | E12: OPS | F12: Vendor console | G12: Create Railway account, project and billing | H12: Open the Railway account and project in the region chosen above. Set a spend alert — usage-based hosting surprises people. | I12: Done | J12: 1 | K12: 2026-09-18 | L12: 2026-09-23 | M12: rcfworks | N12: 1 | O12: P0-PMO-02 | P12: Project exists in the confirmed region; billing and spend alerts configured | Q12: Guide §10 | R12: Workspace 'rcarr-crypto's Projects'; project 'sponsorX' ID 1c11f29a-b569-4d14-98cf-e97a4d3ae209. PRO PLAN with spend limits set (compute hard $150 / email $25; agent hard $20 / email $20) - that half of the acceptance is met. REOPENED 2026-09-18: the region half is NOT met. Read from the Railway CLI, `region` is null on the service instance in BOTH environments - nothing was ever set explicitly. Railway therefore placed them by default: staging landed on US East, production landed on 'sfo' (San Francisco). The US East chip read in the console on 2026-09-18 was staging's. G-02 requires us-east4-eqdc4a, so production currently violates data residency. Fix is one serviceInstanceUpdate per environment setting region='us-east4-eqdc4a'; closes as soon as that is applied and must happen before Postgres exists under P2-OPS-01, because moving a database region later is exactly what G-02 was written to avoid. 2026-09-18 update: multiRegionConfig set to us-east4-eqdc4a on web in BOTH environments (the legacy `region` field is inert - Railway reads multiRegionConfig). web's running deployment still reports sfo and will move on its next redeploy, which this session is not permitted to trigger. CLOSED 2026-09-18: web's running deployment now reports multiRegionConfig {us-east4-eqdc4a: 1}. Both halves of the acceptance are met - region confirmed in the live deployment, billing and spend limits configured. 2026-09-18: set back to In progress under rcfworks at the user's instruction, so the whole Railway / Clerk / backend-setup cluster reads as one owned workstream. THE WORK ITSELF IS FINISHED and was completed on 2026-09-18 - the Date Done column still holds it. Status here signals ownership of the workstream, not that the work is outstanding. CLOSED 2026-09-23, verified in the console. PROJECT: sponsorX, environments production and staging; production runs web + Postgres-production. REGION: web is US East (Virginia, USA), matching A7's us-east4-eqdc4a. BILLING: Pro Workspace, card ending 1115, billing email rcarr@icarrefound.org. OWNERSHIP: the workspace reads 'rcarr-crypto's Project' — a personal workspace, confirmed by the user as the owner's own account and the one holding Pro; that is the BTG-controlled account for this purpose and the question is settled. SPEND ALERTS: compute hard limit $50 / email alert $25; agent hard limit $5 / alert $0 because nothing here uses Railway agents. Current usage $1.35 with $2.71 projected for the period against $20 included, so the limits are headroom against a runaway rather than a budget.
A13: 2 | B13: P0-PMO-07 | C13: 0 | D13: Foundation & Decisions | E13: PMO | F13: Document | G13: Author the RBAC matrix (§38 deliverable) | H13: A table: each of the 12 user roles down one side, every Phase 1 resource across the top, allow/deny in each cell. This table literally becomes the automated test suite later, so it has to be agreed by humans first. | I13: Done | J13: 3 | K13: 2026-09-14 | L13: 2026-09-14 | M13: rcfworks | N13: 3 | P13: All 12 roles × every Phase 1 resource, in a table, agreed — this becomes the authz test suite | Q13: §8, §38 | R13: 2026-09-14 DRAFTED, awaiting sign-off - documentation/SponsorX-RBAC-Matrix.md v0.1. 12 roles from blueprint S8 (which the graphify-converted copy has LOST - read the Drive original). Roles map 1:1 to the Prisma Role enum in the Implementation Guide V2. Task wording amended by PR in the phase doc: the original described a flat roles x resources grid, which cannot express ownership (PROPERTY_MGR may read own-property athletes, not other-property). Now 4 axes: role x resource(+field) x action x ownership. 85 active test cases + 3 deferred, in the S09 CASES format ready to lift into authz.matrix.test.ts. NOT DONE: acceptance requires 'agreed'; 5 open decisions D1-D5 need human answers (D1 guardian accept for minor - S8 explicitly defers; D2 athlete sees sponsor price; D3 property mgr sees roster earnings - legal; D4 sales sees athlete rates; D5 athlete sees own score). | DONE 2026-09-14. All five decisions adopted at the RESTRICTIVE option, so each can only be loosened later by a deliberate recorded decision: D1 guardian authorises AND athlete accepts (both required for a minor); D2 athlete does not see sponsor price; D3 property mgr does not see individual earnings; D4 sales cannot see athlete rates; D5 athlete sees tier not factor scores. Matrix promoted to v1.0, 91 active test cases, no deferred rows. D1 and D3 remain SUBJECT TO LEGAL CONFIRMATION - D1 ties to the open guardian e-signature question, D3 to whatever school/club agreements say; confirmation can only ratify or tighten, so neither blocks.
A14: 2.5 | B14: P0-OPS-06 | C14: 0 | D14: Foundation & Decisions | E14: OPS | F14: Vendor console | G14: Register the SponsorX domain and hold the DNS | H14: Buy the domain the whole product is addressed at, and keep control of its DNS. Nothing in the programme registers one, yet three separate threads assume it exists. | I14: Done | J14: 1 | K14: 2026-09-18 | L14: 46288 | M14: management | N14: 1 | O14: None | P14: Domain registered to a BTG-controlled account with auto-renew and registrar lock on; DNS managed somewhere the team can add records; the chosen name recorded in .claude/stack-decision.md | Q14: §38, Guide §10 | R14: Raised 2026-09-18. NOT A TASK DEPENDENCY - a real-world prerequisite the Depends On column cannot express, which is why three tasks have been quietly waiting on it. Blocks: P0-OPS-03 (a Clerk PRODUCTION instance needs a domain - that row has sat In progress since 2026-09-14 for exactly this), P2-OPS-11 (HTTP error rate needs web to be reachable, and web has no public domain in either environment), and SHORT_LINK_DOMAIN for the fan QR and tracking routes, which Guide §10 says must be owned rather than a third-party shortener. FINDING 2026-09-18: sponsorx.com is ALREADY REGISTERED to someone else (AWS nameservers), as are sponsorx.io, .app, .co and .pro. The Implementation Guide assumes sponsorx.com and app.sponsorx.com throughout, so that assumption is dead and the guide needs correcting once a name is chosen. No DNS records found for: sponsorx.us, sponsorx.dev, sponsorx.team, sponsorx.network, sponsorx.sport, btgsponsorx.com, joinsponsorx.com - availability must still be confirmed at a registrar, since no DNS is not the same as unregistered. IN PROGRESS 2026-09-18, HANDED TO MANAGEMENT: the developer has no card access, so the purchase itself is management's to complete. Everything up to payment is prepared - Cloudflare account exists (Rcarr@icarrefound.org), RECOMMENDED NAME sponsorx.us at $6.50/yr (exact brand, and the .us US-nexus requirement matches NIL being US law and the US-only residency decision); fallback sponsorx.net at $11.86 if WHOIS privacy is wanted, because .us publishes registrant data with no redaction option. Registrant: Organization = the legal entity (NOT a personal name), contact rcarr@icarrefound.org, +1 443 985 3256, 2601 Pennsylvania Ave, Baltimore, MD 21217, United States. After purchase: turn auto-renew AND registrar lock on, add no DNS records yet. | 2026-09-28: sponsorx.net NOW SERVES PRODUCTION. Railway custom domain on production web (CNAME @ → c0ojxycv.up.railway.app, DNS only; TXT _railway-verify), verified, TLS certificate valid; public pages 200, portals redirect to /login, sign-in page uses the live Clerk instance (clerk.sponsorx.net). Records added in the Cloudflare dashboard by the user — the repo's CLOUDFLARE_API_TOKEN is account-scoped with no DNS permission on the zone. Row stays In progress: auto-renew + registrar lock and the stack-decision.md note are the acceptance items not yet confirmed. | 2026-10-09: DONE — every clause was met on 2026-09-23 and recorded in .claude/stack-decision.md ("The domain — sponsorx.net"): Cloudflare account, auto-renew on (2027-08-19), registrar lock on, DNS on Cloudflare. Re-checked 2026-10-09: whois clientTransferProhibited, expires 2027-09-18, NS garrett/raegan.ns.cloudflare.com, https://sponsorx.net 200. The row was left In progress by mistake.
A15: 3 | B15: P0-OPS-03 | C15: 0 | D15: Foundation & Decisions | E15: OPS | F15: Vendor console | G15: Create Clerk application (dev + production instances) | H15: Create the Clerk account with separate dev and production instances. Clerk handles login, passwords and MFA only — it never stores who belongs to which tenant or what they can do. | I15: Done | J15: 1 | K15: 2026-09-14 | L15: 46311 | M15: rcfworks | N15: 2 | P15: Both instances exist (amended 2026-10-16 by the user: the MFA half is P2-INT-02's, closed when Clerk Pro is bought at launch) | Q15: Addendum A4, §26 | R15: 2026-10-16 DONE (rcfworks, the user's decision): both instances exist and production signs in on clerk.sponsorx.net; the MFA half of the old Done-when moved to P2-INT-02, which says the same thing. | 2026-09-14: Clerk account created, DEVELOPMENT instance 'SponsorXDev' exists. Free tier, no Pro purchased - MFA is Pro-only ($20/mo) and is a launch cost per provisioning sequence step 16, not now. PRODUCTION INSTANCE DELIBERATELY DEFERRED at the user's direction: it needs a domain BTG does not have yet, and there is nothing to deploy. Task stays In progress because 'Done when' requires both instances. No Clerk SDK installed - that is code work behind the B0 no-new-dependencies rule. 2026-09-21: PRODUCTION INSTANCE CREATED, so both instances now exist. The 2026-09-14 development instance 'SponsorXDev' was gone from the ICARRE FOUNDATION workspace (Applications list empty), so the application was recreated as 'SponsorX' - one Clerk application holds BOTH instances, which is why the old Dev-suffixed name was wrong. Settings: Consumer project type (NOT B2B - B2B turns on Clerk Organizations for roles, and Addendum A4 puts tenancy and roles in Postgres); Organizations off for the same reason; sign-in Email only, with phone off per G-06 (SMS out of Phase 1) and Google off to avoid a Google Cloud OAuth consent screen no task covers. app_3JcMVfla0x1djZe95U38EcsxfRP; dev ins_3JcMVgKOWFsPxVEQknFjjWg8d8k; prod ins_3JcQVIy69lPJqNJb4XcS0PHDe2o. PRODUCTION DOMAIN sponsorx.net, VERIFIED - the five CNAMEs were written by Cloudflare Domain Connect ('Configure automatically'), not by hand, which also guarantees they are DNS-only rather than proxied: clerk -> frontend-api.clerk.services, accounts -> accounts.clerk.services, clkmail -> mail.p7c0i8jb74bp.clerk.services, clk._domainkey -> dkim1..., clk2._domainkey -> dkim2... All five confirmed resolving on 1.1.1.1 and 8.8.8.8, and SSL has since ISSUED for both clerk.sponsorx.net and accounts.sponsorx.net (Google Trust Services WE1, valid from 2026-09-21). No _dmarc TXT exists on the zone; Clerk did not add one and it is not one of the five, so it did not block verification. STILL IN PROGRESS - the 'Done when' has two halves and only the first is met. On the Hobby plan ALL THREE MFA strategies are Pro-badged: SMS verification (also unavailable because phone numbers are off, correct per G-06), Authenticator application, and Backup codes; 'Require multi-factor authentication' needs at least one strategy enabled, so it is unreachable too. This matches the 2026-09-14 finding and stays a launch cost at provisioning sequence step 16. Keys NOT captured anywhere yet - pk_live/sk_live go into Railway when P2-INT-01 installs the SDK, not into a local .env.local, per the B0 no-new-dependencies rule. 2026-09-21 DECISION: Phase 1 proceeds on the Hobby plan; the MFA half of this row's 'Done when' is deferred to launch by choice and the reasoning is recorded on P2-INT-02. | 2026-10-02 (HeckerCreatives, via Claude): NEW FINDING: the development instance is at Clerk's 100-user cap ('You have reached your limit of 100 users') — no new identity can be created: a new developer cannot sign up, and browser tests or walkthroughs needing a login they have not created before fail. Clear stale test users in the dashboard (e2e.* and old QA addresses). Not done here — deleting identities is the owner's call. | 2026-10-09 AUDIT: NOT MET — both instances exist (production clerk.sponsorx.net serves sign-in), but the production instance has NO MFA strategy enabled (authenticator app, backup codes, phone all off; second factor not required — read from clerk.sponsorx.net/v1/environment). Needs Clerk Pro, deferred to launch on 2026-09-21. Closes with P2-INT-02.
A16: 7 | B16: P0-DATA-01 | C16: 0 | D16: Foundation & Decisions | E16: DATA | F16: Document | G16: Define the metric provenance taxonomy | H16: Agree the five honesty labels for numbers: verified by API, verified by a human checking, self-reported by the athlete, estimated, or attributed. Write the rule for when each applies. | I16: Done | J16: 1 | K16: 2026-09-14 | L16: 2026-09-14 | M16: rcfworks | N16: 1 | P16: The five labels (verified-API / verified-manual / self-reported / estimated / attributed) defined with a written rule for when each applies | Q16: §22, §26 | R16: 2026-09-14 DRAFTED - documentation/SponsorX-Metric-Provenance-Taxonomy.md v0.1. Five labels defined with qualification rules and who may assign each. Adds the two rules the blueprint never gave: a DERIVED value takes the weakest of its inputs, and a ROLLUP takes the weakest of its parts; ATTRIBUTED propagates upward and sits off the strength ladder. Proposes splitting provenance into two fields - source (the five labels) and retrieval (the named path) - because the codebase already uses both conventions in one field. AUDIT FOUND 6 ISSUES, 3 high severity and 2 of those on the sponsor-facing report: F-1 campaign Total Views labelled VERIFIED_MANUAL but built from SELF_REPORTED athlete figures; F-2 Cost per View / per Engagement inherit the wrong provenance; F-3 'Primary Age' and 'Core Age' are audience demographics, out of scope for Phase 1 - remove, do not relabel. NOT DONE: 2 open decisions D1 (does VERIFIED_API cover our own instrumentation) and D2 (is the weakest-input rollup rule too harsh). No code changed. | FIXES APPLIED 2026-09-14 to src/lib/fixtures.ts: F-1 sponsor-report Total Views and Engagements VERIFIED_MANUAL -> SELF_REPORTED (rollups of athlete-reported figures); F-2 Cost per View and Cost per Engagement follow their weakest input; F-3 'Primary Age' and 'Core Age' REMOVED from property and athlete stats - demographics are out of Phase 1 scope with no retrieval path. Each edit carries a comment citing the rule. F-4/F-5/F-6 outstanding, none on the sponsor report. BUILD VERIFIED 2026-09-14: npm ci + npm run build clean (27 routes, 21 static pages), tsc --noEmit clean, lint 0 errors / 1 pre-existing warning in t/[code]/route.ts. | DONE 2026-09-14, both decisions taken. D1: a SIXTH label added - VERIFIED_SYSTEM for events SponsorX records itself (QR scan, redemption), displayed as 'measured', and it outranks VERIFIED_API because we can audit ours end to end. VERIFIED_API narrows to mean an outside platform and its name is finally accurate. Costs one Prisma enum value. D2: rollups SHOW THEIR MIX with percentages, falling back to the weakest label only where a single value must fit. Implemented: SourceLabel takes six labels; Leads Generated and Rewards Redeemed -> VERIFIED_SYSTEM (F-4). Build, typecheck and lint clean. STILL OPEN, neither on the sponsor report: F-5 property stats need stated evidence; F-6 homepage counters need the two-field source/retrieval change, which is a fixture SHAPE change and must land in the Prisma model too.
A17: 8 | B17: P0-PMO-08 | C17: 0 | D17: Foundation & Decisions | E17: PMO | F17: Document | G17: Author the Zoho module + field mapping document (§38 deliverable) | H17: Map every SponsorX record to its Zoho equivalent, field by field, and say which system wins when they disagree. Without this, the two systems quietly drift apart. | I17: Done | J17: 3 | K17: 2026-09-11 | L17: 2026-09-14 | M17: rcfworks | N17: 2 | P17: Every object in §18 mapped field-by-field, with direction and system-of-record owner per field | Q17: §18, §38 | R17: 2026-09-14 CORRECTION: row read Ready but the deliverable shipped 2026-09-11 - documentation/SponsorX-Zoho-Field-Mapping.md, all nine S18 objects mapped field by field. The Claude outputs copy never received that update. Awaiting review; one open item O-1 (Invoice/Payment Reference mapping) which is why Books credentials stay deferred. | REVIEWED + APPROVED 2026-09-14 by rcfworks. Approved WITH O-1 CARRIED. Eight of the nine S18 objects are mapped field by field; the ninth (Invoice/Payment Reference) stays open as O-1 because it depends on the Phase 1 payment policy, which is deliberately on the backburner. The eight mapped objects are what the sync gets built from, so holding the whole document for a deferred question helps nobody. Reopen if O-1 changes any mapped field.
A18: 9 | B18: P0-OPS-02 | C18: 0 | D18: Foundation & Decisions | E18: OPS | F18: Vendor console | G18: Create Cloudflare R2 account and two buckets | H18: Set up Cloudflare R2 with two buckets: one private for contracts and draft creative, one public for published video. Different security rules — they must not share a policy. | I18: Done | J18: 1 | K18: 2026-09-18 | L18: 2026-09-21 | M18: rcfworks | N18: 2 | O18: P0-PMO-02 | P18: Private and public buckets exist with separate policies; region set explicitly | Q18: Addendum A8 | R18: DONE 2026-09-21. R2 WAS NOT ENABLED AT ALL until today - this row had sat In progress since 2026-09-18 with empty notes, and the account's R2 page was still the activation screen. Worth knowing that an In progress row with no notes may mean 'not started'. Both buckets now exist, both pinned to EASTERN NORTH AMERICA (ENAM) by an explicit location hint. THE DEFAULT WOULD HAVE BEEN WRONG: Cloudflare's 'Automatic' placement offered ASIA PACIFIC on both creation screens, which would have put athlete agreements and minors' data outside the US-only residency decision (G-02) and a continent away from Railway's us-east4. Bucket location is PERMANENT, so this was a one-shot choice. Note R2's 'Specify jurisdiction' option does not help here - its only jurisdictions are eu and fedramp - so a location hint is the correct mechanism. SEPARATE POLICIES, which is the acceptance: sponsorx-private has Public Access DISABLED and no public hostname at all; sponsorx-public has the Public Development URL enabled at https://pub-7d82e60511bb4bdc9198b547f4e37fe9.r2.dev. VERIFIED FROM OUTSIDE THE ACCOUNT: the public host answers 404 from R2 itself (Server: cloudflare) for a missing object, proving it serves; the S3 API endpoint returns 400 for unsigned requests to BOTH buckets, proving that path always requires a signature. S3 API ENDPOINT for the backend's S3_ENDPOINT: https://0a10106029579f2496ccf0956745525c.r2.cloudflarestorage.com (the hex string is the Cloudflare account id; not a secret on its own). STILL TO DO, BELONGS ELSEWHERE: (1) the r2.dev URL is rate-limited and Cloudflare says explicitly it is not for production - a CUSTOM DOMAIN such as cdn.sponsorx.net should replace it before launch, and it is available today because sponsorx.net is in this same Cloudflare account. (2) A CORS POLICY on sponsorx-private is required before a phone can PUT to a presigned URL from a browser - cross-origin uploads fail without it. That belongs to P2-BE-08 once the app's real hostnames are known.
